Workbook
Name _________________________wrn1: {#N/A,#N/A,FALSE,"Summary";#N/A,#N/A,FALSE,"A-01";#N/A,#N/A,FALSE,"A-03";#N/A,#N/A,FALSE,"A-04";#N/A,#N/A,FALSE,"A-06"}
Name ________________________wrn1: {#N/A,#N/A,FALSE,"Summary";#N/A,#N/A,FALSE,"A-01";#N/A,#N/A,FALSE,"A-03";#N/A,#N/A,FALSE,"A-04";#N/A,#N/A,FALSE,"A-06"}
Name _______________________wrn1: {#N/A,#N/A,FALSE,"Summary";#N/A,#N/A,FALSE,"A-01";#N/A,#N/A,FALSE,"A-03";#N/A,#N/A,FALSE,"A-04";#N/A,#N/A,FALSE,"A-06"}
Name _____________________wrn1: {#N/A,#N/A,FALSE,"Summary";#N/A,#N/A,FALSE,"A-01";#N/A,#N/A,FALSE,"A-03";#N/A,#N/A,FALSE,"A-04";#N/A,#N/A,FALSE,"A-06"}
Name ____________________wrn1: {#N/A,#N/A,FALSE,"Summary";#N/A,#N/A,FALSE,"A-01";#N/A,#N/A,FALSE,"A-03";#N/A,#N/A,FALSE,"A-04";#N/A,#N/A,FALSE,"A-06"}
Name ___________________wrn1: {#N/A,#N/A,FALSE,"Summary";#N/A,#N/A,FALSE,"A-01";#N/A,#N/A,FALSE,"A-03";#N/A,#N/A,FALSE,"A-04";#N/A,#N/A,FALSE,"A-06"}
Name __________________wrn1: {#N/A,#N/A,FALSE,"Summary";#N/A,#N/A,FALSE,"A-01";#N/A,#N/A,FALSE,"A-03";#N/A,#N/A,FALSE,"A-04";#N/A,#N/A,FALSE,"A-06"}
Name _________________wrn1: {#N/A,#N/A,FALSE,"Summary";#N/A,#N/A,FALSE,"A-01";#N/A,#N/A,FALSE,"A-03";#N/A,#N/A,FALSE,"A-04";#N/A,#N/A,FALSE,"A-06"}
Name ________________wrn1: {#N/A,#N/A,FALSE,"Summary";#N/A,#N/A,FALSE,"A-01";#N/A,#N/A,FALSE,"A-03";#N/A,#N/A,FALSE,"A-04";#N/A,#N/A,FALSE,"A-06"}
Name _______________wrn1: {#N/A,#N/A,FALSE,"Summary";#N/A,#N/A,FALSE,"A-01";#N/A,#N/A,FALSE,"A-03";#N/A,#N/A,FALSE,"A-04";#N/A,#N/A,FALSE,"A-06"}
Name ______________wrn1: {#N/A,#N/A,FALSE,"Summary";#N/A,#N/A,FALSE,"A-01";#N/A,#N/A,FALSE,"A-03";#N/A,#N/A,FALSE,"A-04";#N/A,#N/A,FALSE,"A-06"}
Name _____________wrn1: {#N/A,#N/A,FALSE,"Summary";#N/A,#N/A,FALSE,"A-01";#N/A,#N/A,FALSE,"A-03";#N/A,#N/A,FALSE,"A-04";#N/A,#N/A,FALSE,"A-06"}
Name ____________wrn1: {#N/A,#N/A,FALSE,"Summary";#N/A,#N/A,FALSE,"A-01";#N/A,#N/A,FALSE,"A-03";#N/A,#N/A,FALSE,"A-04";#N/A,#N/A,FALSE,"A-06"}
Name ___________wrn1: {#N/A,#N/A,FALSE,"Summary";#N/A,#N/A,FALSE,"A-01";#N/A,#N/A,FALSE,"A-03";#N/A,#N/A,FALSE,"A-04";#N/A,#N/A,FALSE,"A-06"}
Name __________wrn1: {#N/A,#N/A,FALSE,"Summary";#N/A,#N/A,FALSE,"A-01";#N/A,#N/A,FALSE,"A-03";#N/A,#N/A,FALSE,"A-04";#N/A,#N/A,FALSE,"A-06"}
Name _________tcm06: {"Aneh",#N/A,FALSE,"Sheet1"}
Name _________tcm4: {"Aneh",#N/A,FALSE,"Sheet1"}
Name _________wrn1: {#N/A,#N/A,FALSE,"Summary";#N/A,#N/A,FALSE,"A-01";#N/A,#N/A,FALSE,"A-03";#N/A,#N/A,FALSE,"A-04";#N/A,#N/A,FALSE,"A-06"}
Name ________AAL1: {#N/A,#N/A,FALSE,"Summary";#N/A,#N/A,FALSE,"A-01";#N/A,#N/A,FALSE,"A-03";#N/A,#N/A,FALSE,"A-04";#N/A,#N/A,FALSE,"A-06"}
Name ________ALA1: {#N/A,#N/A,FALSE,"Summary";#N/A,#N/A,FALSE,"A-01";#N/A,#N/A,FALSE,"A-03";#N/A,#N/A,FALSE,"A-04";#N/A,#N/A,FALSE,"A-06"}
Name ________wrn1: {#N/A,#N/A,FALSE,"Summary";#N/A,#N/A,FALSE,"A-01";#N/A,#N/A,FALSE,"A-03";#N/A,#N/A,FALSE,"A-04";#N/A,#N/A,FALSE,"A-06"}
Name _______AAL1: {#N/A,#N/A,FALSE,"Summary";#N/A,#N/A,FALSE,"A-01";#N/A,#N/A,FALSE,"A-03";#N/A,#N/A,FALSE,"A-04";#N/A,#N/A,FALSE,"A-06"}
Name _______ALA1: {#N/A,#N/A,FALSE,"Summary";#N/A,#N/A,FALSE,"A-01";#N/A,#N/A,FALSE,"A-03";#N/A,#N/A,FALSE,"A-04";#N/A,#N/A,FALSE,"A-06"}
Name _______tcm06: {"Aneh",#N/A,FALSE,"Sheet1"}
Name _______tcm4: {"Aneh",#N/A,FALSE,"Sheet1"}
Name _______wrn1: {#N/A,#N/A,FALSE,"Summary";#N/A,#N/A,FALSE,"A-01";#N/A,#N/A,FALSE,"A-03";#N/A,#N/A,FALSE,"A-04";#N/A,#N/A,FALSE,"A-06"}
Name ______AAL1: {#N/A,#N/A,FALSE,"Summary";#N/A,#N/A,FALSE,"A-01";#N/A,#N/A,FALSE,"A-03";#N/A,#N/A,FALSE,"A-04";#N/A,#N/A,FALSE,"A-06"}
Name ______ab1: {"AHLGANDG",#N/A,FALSE,"GANDG";"OSGANDG",#N/A,FALSE,"GANDG"}
Name ______abc1: {"AHLGANDG",#N/A,FALSE,"GANDG";"OSGANDG",#N/A,FALSE,"GANDG"}
Name ______ALA1: {#N/A,#N/A,FALSE,"Summary";#N/A,#N/A,FALSE,"A-01";#N/A,#N/A,FALSE,"A-03";#N/A,#N/A,FALSE,"A-04";#N/A,#N/A,FALSE,"A-06"}
Name ______rng01: ROW(#REF!)-1
Name ______rng11: SIGN(ROW(#REF!))
Name ______tcm06: {"Aneh",#N/A,FALSE,"Sheet1"}
Name ______tcm4: {"Aneh",#N/A,FALSE,"Sheet1"}
Name ______tes2: 0
Name ______tue56: {#N/A,#N/A,FALSE,"RR-T";#N/A,#N/A,FALSE,"RR-2";#N/A,#N/A,FALSE,"RR-3";#N/A,#N/A,FALSE,"RR-4";#N/A,#N/A,FALSE,"RR-5";#N/A,#N/A,FALSE,"RR-6";#N/A,#N/A,FALSE,"RR-7";#N/A,#N/A,FALSE,"RR-8"}
Name _____AAL1: {#N/A,#N/A,FALSE,"Summary";#N/A,#N/A,FALSE,"A-01";#N/A,#N/A,FALSE,"A-03";#N/A,#N/A,FALSE,"A-04";#N/A,#N/A,FALSE,"A-06"}
Name _____ab1: {"AHLGANDG",#N/A,FALSE,"GANDG";"OSGANDG",#N/A,FALSE,"GANDG"}
Name _____abc1: {"AHLGANDG",#N/A,FALSE,"GANDG";"OSGANDG",#N/A,FALSE,"GANDG"}
Name _____ALA1: {#N/A,#N/A,FALSE,"Summary";#N/A,#N/A,FALSE,"A-01";#N/A,#N/A,FALSE,"A-03";#N/A,#N/A,FALSE,"A-04";#N/A,#N/A,FALSE,"A-06"}
Name _____rng01: ROW(#REF!)-1
Name _____rng11: SIGN(ROW(#REF!))
Name _____tcm06: {"Aneh",#N/A,FALSE,"Sheet1"}
Name _____tcm4: {"Aneh",#N/A,FALSE,"Sheet1"}
Name _____tes2: 0
Name _____tue56: {#N/A,#N/A,FALSE,"RR-T";#N/A,#N/A,FALSE,"RR-2";#N/A,#N/A,FALSE,"RR-3";#N/A,#N/A,FALSE,"RR-4";#N/A,#N/A,FALSE,"RR-5";#N/A,#N/A,FALSE,"RR-6";#N/A,#N/A,FALSE,"RR-7";#N/A,#N/A,FALSE,"RR-8"}
Name ____1__123Graph_ACHART_1: [2]OVERBURDEN!$D$25:$O$25
Name ____10__123Graph_ACHART_21: [2]OVERBURDEN!$T$46:$U$46
Name ____11__123Graph_ACHART_22: [2]OVERBURDEN!$T$71:$U$71
Name ____12__123Graph_ACHART_3: [2]SUBKON!$C$41:$N$41
Name ____13__123Graph_ACHART_4: [2]SUBKON!$C$63:$N$63
Name ____14__123Graph_BCHART_1: [2]OVERBURDEN!$D$26:$O$26
Name ____15__123Graph_BCHART_13: [2]MAINTENANCE!$C$35:$N$35
Name ____16__123Graph_BCHART_15: [2]MAINTENANCE!$C$56:$H$56
Name ____17__123Graph_BCHART_16: [2]SUBKON!$C$20:$N$20
Name ____18__123Graph_BCHART_17: [2]OVERBURDEN!$D$47:$O$47
Name ____19__123Graph_BCHART_18: [2]OVERBURDEN!$D$72:$O$72
Name ____2__123Graph_ACHART_13: [2]MAINTENANCE!$C$34:$N$34
Name ____20__123Graph_BCHART_19: [2]MAINTENANCE!$C$56:$N$56
Name ____21__123Graph_BCHART_2: [2]MAINTENANCE!$C$17:$N$17

Sheet Summary v1
E3: Loading FR | F3: + | G3: Hauling FR | H3: + | J3: Supporting FR | O3: Dewatering | P3: = | Q3: Total Activity-based FR (l/bcm)
E5: =G41 -> 0.15496548 | F5: + | G5: =G53 -> 0.70277778 | H5: + | J5: =P26 -> 0.21993344 | N5: + | O5: =Y42 -> #REF! | P5: = | R5: =E5+G5+J5+O5 -> #REF!
F9: Loading & Hauling Formula | M9: Supporting & Dewatering Formula
B22: Loading & Hauling | I22: Supporting | R22: Dewatering
B24: Loading
B25: Activity | C25: Unit Type (list) | D25: Qty (unit) | E25: Fuel Cons (ltr/hr) | F25: Prodty (BCM/hr) | G25: Fuel Ratio (l/BCM) | I25: Unit Type | J25: Qty (unit) | K25: PA | L25: UA | M25: EWH (hr) | N25: Fuel Cons (ltr/hr) | O25: Prod (BCM) | P25: Fuel Ratio (l/BCM) | R25: Unit Type | S25: Qty (unit) | T25: PA | U25: UA | V25: EWH (hr) | W25: Fuel Cons (ltr/hr) | X25: Prod (BCM/hr) | Y25: Fuel Ratio (l/BCM)
A26: EX2600-6 | B26: Loading | C26: EX26007 | D26: =VLOOKUP(C26,'Equipment Summary'!A:D,4,0) -> 3 | E26: =VLOOKUP($A26,Ref_fuel!$B:$E,4,) -> 187 | F26: =VLOOKUP(C26,'Equipment Summary'!A:E,5,0) -> 920 | G26: =SUMPRODUCT(D26:D32,E26:E32)/SUMPRODUCT(D26:D32,F26:F32) -> 0.15496548 | I26: CAT14M3 | J26: =SUMIF('Equipment Summary'!$A$13:$A$54,$I26,'Equipment Summary'!$D$13:$D$54) -> 3 | K26: 0.9 | L26: 0.53 | M26: =K26*L26*24*360 -> 4121.28 | N26: =VLOOKUP($I26,Ref_fuel!$B:$E,4,) -> 16 | O26: =1.05*86930000 -> 91276500 | P26: =SUMPRODUCT(M26:M33,N26:N33,J26:J33)/O26 -> 0.21993344 | Q26: PUMP, KSB, LSA 6X6-25, CAT C27 | R26: DNDLSA6X8 | S26: =SUMIF('Equipment Summary'!$A$13:$A$54,$R26,'Equipment Summary'!$D$13:$D$54) -> 6 | T26: 0.9 | U26: 0.63 | V26: =T26*U26*24*360 -> 4898.88 | W26: =VLOOKUP($Q26,Ref_fuel!$B:$E,4,) -> 40 | X26: =O26 -> 91276500 | Y26: =SUMPRODUCT(S26:S40,V26:V40,W26:W40)/X26 -> #REF!
A27: PC1250-11R | C27: PC125011R | D27: =VLOOKUP(C27,'Equipment Summary'!A:D,4,0) -> 18 | E27: =VLOOKUP($A27,Ref_fuel!$B:$E,4,) -> 59 | F27: =VLOOKUP(C27,'Equipment Summary'!A:E,5,0) -> 310 | I27: D155-6 | J27: =SUMIF('Equipment Summary'!$A$13:$A$54,$I27,'Equipment Summary'!$D$13:$D$54) -> 8 | K27: 0.9 | L27: 0.53 | M27: =K27*L27*24*360 -> 4121.28 | N27: =N28 -> 29 | R27: DREDGER 12/10 | S27: =SUMIF('Equipment Summary'!$A$13:$A$54,$R27,'Equipment Summary'!$D$13:$D$54) -> 0 | T27: 0.9 | U27: 0.63 | V27: =T27*U27*24*360 -> 4898.88 | W27: =VLOOKUP($R27,#REF!,5,) -> #REF!
A28: PC1250SP8 | C28: PC1250SP8 | D28: =VLOOKUP(C28,'Equipment Summary'!A:D,4,0) -> 12 | E28: =VLOOKUP($A28,Ref_fuel!$B:$E,4,) -> 64 | F28: =VLOOKUP(C28,'Equipment Summary'!A:E,5,0) -> 320 | I28: D155A6A | J28: =SUMIF('Equipment Summary'!$A$13:$A$54,$I28,'Equipment Summary'!$D$13:$D$54) -> 4 | K28: 0.9 | L28: 0.53 | M28: =K28*L28*24*360 -> 4121.28 | N28: =VLOOKUP($I28,Ref_fuel!$B:$E,4,) -> 29 | Q28: DREDGER 12/10 | R28: DREDGERPUMP | S28: =SUMIF('Equipment Summary'!$A$13:$A$54,$R28,'Equipment Summary'!$D$13:$D$54) -> 7 | T28: 0.9 | U28: 0.63 | V28: =T28*U28*24*360 -> 4898.88 | W28: =VLOOKUP($Q28,#REF!,5,) -> #REF!
A29: PC2000-11R | C29: PC200011R | D29: =VLOOKUP(C29,'Equipment Summary'!A:D,4,0) -> 18 | E29: =VLOOKUP($A29,Ref_fuel!$B:$E,4,) -> 100 | F29: =VLOOKUP(C29,'Equipment Summary'!A:E,5,0) -> 820 | I29: D155A6R | J29: =SUMIF('Equipment Summary'!$A$13:$A$54,$I29,'Equipment Summary'!$D$13:$D$54) -> 36 | K29: 0.9 | L29: 0.53 | M29: =K29*L29*24*360 -> 4121.28 | N29: =VLOOKUP($I29,Ref_fuel!$B:$E,4,) -> 29 | Q29: DRHY85/160B | R29: DRHY85160B | S29: =SUMIF('Equipment Summary'!$A$13:$A$54,$R29,'Equipment Summary'!$D$13:$D$54) -> 9 | T29: 0.9 | U29: 0.63 | V29: =T29*U29*24*360 -> 4898.88 | W29: =VLOOKUP($Q29,#REF!,5,) -> #REF!
A30: PC2000-8 | C30: PC20008 | D30: =VLOOKUP(C30,'Equipment Summary'!A:D,4,0) -> 16 | E30: =VLOOKUP($A30,Ref_fuel!$B:$E,4,) -> 100 | F30: =VLOOKUP(C30,'Equipment Summary'!A:E,5,0) -> 480 | I30: D375-6 | J30: =SUMIF('Equipment Summary'!$A$13:$A$54,$I30,'Equipment Summary'!$D$13:$D$54) -> 10 | K30: 0.9 | L30: 0.53 | M30: =K30*L30*24*360 -> 4121.28 | N30: =N31 -> 67 | Q30: GENSET, KOMATSU, EGS380-6 | R30: EGS380-6 | S30: =SUMIF('Equipment Summary'!$A$13:$A$54,$R30,'Equipment Summary'!$D$13:$D$54) -> 3 | T30: 0.9 | U30: 0.63 | V30: =T30*U30*24*360 -> 4898.88 | W30: =VLOOKUP($Q30,#REF!,5,) -> #REF!
A31: PC 200-8 | C31: PC3400 | D31: =VLOOKUP(C31,'Equipment Summary'!A:D,4,0) -> 2 | E31: =VLOOKUP($A31,Ref_fuel!$B:$E,4,) -> 12 | F31: =VLOOKUP(C31,'Equipment Summary'!A:E,5,0) -> 940 | I31: D375A6R | J31: =SUMIF('Equipment Summary'!$A$13:$A$54,$I31,'Equipment Summary'!$D$13:$D$54) -> 20 | K31: 0.9 | L31: 0.53 | M31: =K31*L31*24*360 -> 4121.28 | N31: =VLOOKUP($I31,Ref_fuel!$B:$E,4,) -> 67 | R31: EWP420 | S31: =SUMIF('Equipment Summary'!$A$13:$A$54,$R31,'Equipment Summary'!$D$13:$D$54) -> 40 | T31: 0.9 | U31: 0.63 | V31: =T31*U31*24*360 -> 4898.88 | W31: =W33 -> #REF!
A32: PC300-8 | C32: PC3400EX11 | D32: =VLOOKUP(C32,'Equipment Summary'!A:D,4,0) -> 1 | E32: =VLOOKUP($A32,Ref_fuel!$B:$E,4,) -> 21 | F32: =VLOOKUP(C32,'Equipment Summary'!A:E,5,0) -> 1160 | I32: D85ESS-2 | J32: =SUMIF('Equipment Summary'!$A$13:$A$54,$I32,'Equipment Summary'!$D$13:$D$54) -> 0 | K32: 0.9 | L32: 0.53 | M32: =K32*L32*24*360 -> 4121.28 | N32: =VLOOKUP($I32,Ref_fuel!$B:$E,4,) -> 27 | Q32: KSB LCC-H200 | R32: KSB | S32: =SUMIF('Equipment Summary'!$A$13:$A$54,$R32,'Equipment Summary'!$D$13:$D$54) -> 6 | T32: 0.9 | U32: 0.63 | V32: =T32*U32*24*360 -> 4898.88 | W32: =VLOOKUP($Q32,#REF!,5,) -> #REF!
A33: PC3400 | I33: GD825A2 | J33: =SUMIF('Equipment Summary'!$A$13:$A$54,$I33,'Equipment Summary'!$D$13:$D$54) -> 49 | K33: 0.9 | L33: 0.53 | M33: =K33*L33*24*360 -> 4121.28 | N33: =VLOOKUP($I33,Ref_fuel!$B:$E,4,) -> 29 | Q33: MF420EX | R33: MEB420EXHV | S33: =SUMIF('Equipment Summary'!$A$13:$A$54,$R33,'Equipment Summary'!$D$13:$D$54) -> 30 | T33: 0.9 | U33: 0.63 | V33: =T33*U33*24*360 -> 4898.88 | W33: =VLOOKUP($Q33,#REF!,5,) -> #REF!
A34: PC3400 | I34: FMX440FT | J34: =SUMIF('Equipment Summary'!$A$13:$A$54,$I34,'Equipment Summary'!$D$13:$D$54) -> 20 | K34: 0.9 | L34: 0.53 | M34: =K34*L34*24*360 -> 4121.28 | N34: =VLOOKUP($I34,Ref_fuel!$B:$E,4,) -> 44 | Q34: MF420EX | R34: MF420E | S34: =SUMIF('Equipment Summary'!$A$13:$A$54,$R34,'Equipment Summary'!$D$13:$D$54) -> 12 | T34: 0.9 | U34: 0.63 | V34: =T34*U34*24*360 -> 4898.88 | W34: =VLOOKUP($Q34,#REF!,5,) -> #REF!
A35: PC400LCSE-8R | I35: FMX440WT | J35: =SUMIF('Equipment Summary'!$A$13:$A$54,$I35,'Equipment Summary'!$D$13:$D$54) -> 2 | K35: 0.9 | L35: 0.53 | M35: =K35*L35*24*360 -> 4121.28 | N35: =VLOOKUP($I35,Ref_fuel!$B:$E,4,) -> 23 | R35: MF420EX | S35: =SUMIF('Equipment Summary'!$A$13:$A$54,$R35,'Equipment Summary'!$D$13:$D$54) -> 6 | T35: 0.9 | U35: 0.63 | V35: =T35*U35*24*360 -> 4898.88 | W35: =VLOOKUP($R35,#REF!,5,) -> #REF!
A36: PC400LCSE-8R | I36: HD7857OTD | J36: =SUMIF('Equipment Summary'!$A$13:$A$54,$I36,'Equipment Summary'!$D$13:$D$54) -> 0 | K36: 0.9 | L36: 0.53 | M36: =K36*L36*24*360 -> 4121.28 | N36: =N37 -> 77 | R36: MF420EXHV | S36: =SUMIF('Equipment Summary'!$A$13:$A$54,$R36,'Equipment Summary'!$D$13:$D$54) -> 20 | T36: 0.9 | U36: 0.63 | V36: =T36*U36*24*360 -> 4898.88 | W36: =VLOOKUP($R36,#REF!,5,) -> #REF!
A37: PC8508R1 | I37: HD7857WT | J37: =SUMIF('Equipment Summary'!$A$13:$A$54,$I37,'Equipment Summary'!$D$13:$D$54) -> 22 | K37: 0.9 | L37: 0.53 | M37: =K37*L37*24*360 -> 4121.28 | N37: =VLOOKUP($I37,Ref_fuel!$B:$E,4,) -> 77 | Q37: MFV290C | R37: MFV290 | S37: =SUMIF('Equipment Summary'!$A$13:$A$54,$R37,'Equipment Summary'!$D$13:$D$54) -> 2 | T37: 0.9 | U37: 0.63 | V37: =T37*U37*24*360 -> 4898.88 | W37: =VLOOKUP($Q37,#REF!,5,) -> #REF!
A38: PC8508R1 | I38: P360CB6X6WT | J38: =SUMIF('Equipment Summary'!$A$13:$A$54,$I38,'Equipment Summary'!$D$13:$D$54) -> 6 | K38: 0.9 | L38: 0.53 | M38: =K38*L38*24*360 -> 4121.28 | N38: =VLOOKUP($I38,Ref_fuel!$B:$E,4,) -> 26 | R38: MFV290C | S38: =SUMIF('Equipment Summary'!$A$13:$A$54,$R38,'Equipment Summary'!$D$13:$D$54) -> 4 | T38: 0.9 | U38: 0.63 | V38: =T38*U38*24*360 -> 4898.88 | W38: =VLOOKUP($R38,#REF!,5,) -> #REF!
A39: PC8508R1 | I39: P360CB6X6 | J39: =SUMIF('Equipment Summary'!$A$13:$A$54,$I39,'Equipment Summary'!$D$13:$D$54) -> 3 | K39: 0.9 | L39: 0.53 | M39: =K39*L39*24*360 -> 4121.28 | N39: =N38 -> 26 | R39: MFV420EXHV | S39: =SUMIF('Equipment Summary'!$A$13:$A$54,$R39,'Equipment Summary'!$D$13:$D$54) -> 20 | T39: 0.9 | U39: 0.63 | V39: =T39*U39*24*360 -> 4898.88 | W39: =VLOOKUP($R39,#REF!,5,) -> #REF!
E40: =(E26*D26)/(F26*D26) -> 0.20326087 | Q40: RF-85MW | R40: RF85MW | S40: =SUMIF('Equipment Summary'!$A$13:$A$54,$R40,'Equipment Summary'!$D$13:$D$54) -> 10 | T40: 0.9 | U40: 0.63 | V40: =T40*U40*24*360 -> 4898.88 | W40: =VLOOKUP($Q40,#REF!,5,) -> #REF!
B41: Loading FR (l/BCM) = | G41: =G26 -> 0.15496548 | I41: Supporting FR (l/BCM) = | P41: =P26 -> 0.21993344
R42: Dewatering KJA & Contractor FR (l/BCM) = | Y42: =Y26 -> #REF!
B44: Hauling (distance 3900 mtr)
B45: Activity | C45: Unit Type (list) | D45: Qty (unit) | E45: Fuel Cons (ltr/hr) | F45: Prodty (BCM/hr) | G45: Fuel Ratio (l/BCM)
A46: FM9CT | B46: Hauling | C46: HD7857 | D46: =VLOOKUP(C46,'Equipment Summary'!A:D,4,0) -> 400 | E46: =VLOOKUP($C46,Ref_fuel!$B:$E,4,) -> 77 | F46: ='Ref_Prodty Hauler per 100mtr'!Q40 -> 109.56522 | G46: =SUMPRODUCT(D46:D51,E46:E51)/SUMPRODUCT(D46:D51,F46:F51) -> 0.70277778
A47: FM9CT | C47: HD7858 | D47: =VLOOKUP(C47,'Equipment Summary'!A:D,4,0) -> 15 | E47: =VLOOKUP($C47,Ref_fuel!$B:$E,4,) -> 77 | F47: =F46 -> 109.56522
A48: FMX440
A49: FMX440
B53: Hauling FR (l/BCM) = | G53: =G46 -> 0.70277778
B58: How the Operation Fuel Ratio (FR) can help Management analyze
B60: 1. If variable Productivity UP, Then FR will be DOWN, this reflect contractor performance
B61: 2. If variable Population UP, Then FR will be UP, this reflect infrastructur performance
B62: 3. If variable Fuel Consumption UP, Then FR will be UP, this reflect equipment condition/age

Sheet Equipment Summary
A1: DUMMY
A3: Unit type list | B3: Item | C3: Activity | D3: Qty (unit) | E3: Productivity (bcm/hr)
A4: EX26007 | B4: Excavator OB | C4: Loading | D4: 3 | E4: 920
A5: PC125011R | B5: Excavator OB | C5: Loading | D5: 18 | E5: 310
A6: PC1250SP8 | B6: Excavator OB | C6: Loading | D6: 12 | E6: 320
A7: PC200011R | B7: Excavator OB | C7: Loading | D7: 18 | E7: 820
A8: PC20008 | B8: Excavator OB | C8: Loading | D8: 16 | E8: 480
A9: PC3400 | B9: Excavator OB | C9: Loading | D9: 2 | E9: 940
A10: PC3400EX11 | B10: Excavator OB | C10: Loading | D10: 1 | E10: 1160
A11: HD7857 | B11: Dump Truck OB | C11: Hauling | D11: 400 | E11: =E12 -> 109.56522 | F11: Based on distance
A12: HD7858 | B12: Dump Truck OB | C12: Hauling | D12: 15 | E12: ='Ref_Prodty Hauler per 100mtr'!Q40 -> 109.56522 | F12: Based on distance
A13: DNDLSA6X8 | B13: Water Pump | C13: Dewatering | D13: 6
A14: DREDGER 12/1 | B14: Water Pump | C14: Dewatering | D14: 2
A15: DREDGERPUMP | B15: Water Pump | C15: Dewatering | D15: 7
A16: DRHY85160B | B16: Water Pump | C16: Dewatering | D16: 9
A17: EGS380-6 | B17: Water Pump | C17: Dewatering | D17: 3
A18: EWP420 | B18: Water Pump | C18: Dewatering | D18: 40
A19: KSB | B19: Water Pump | C19: Dewatering | D19: 6
A20: MEB420EXHV | B20: Water Pump | C20: Dewatering | D20: 30
A21: MF420E | B21: Water Pump | C21: Dewatering | D21: 12
A22: MF-420E | B22: Water Pump | C22: Dewatering | D22: 3
A23: MF420EX | B23: Water Pump | C23: Dewatering | D23: 6
A24: MF420EXHV | B24: Water Pump | C24: Dewatering | D24: 20
... A54: GD825A2 | B54: Motor Grader | C54: Supporting | D54: 49

Sheet Ref_Prodty Hauler per 100mtr
A1: DUMMY
B2: HD785 | C2: Minute | D2: Hour | F2: Speed | G2: 200 m | I2: 200 m
B3: Load | C3: 3.3 | D3: =C3/60 -> 0.055 | F3: Haul | G3: 10 | H3: 25 | I3: 10 | J3: km/hr
B4: Dump | C4: 0.5 | D4: =C4/60 -> 0.0083333333 | F4: Return | G4: 10 | H4: 35 | I4: 10 | J4: km/hr | K4: =K11*60 -> 3.3 | L4: =L11*60 -> 3.84 | M4: =M11*60 -> 0.5 | N4: =N11*60 -> 3.4285714
B5: Capacity | C5: 42 | D5: BCM/trip | K5: Load | L5: Haul | M5: Dump | N5: Return | O5: Cycle time | P5: km | Q5: BCM/HR
B6: PC2000 | C6: =C5*60/C3 -> 763.63636 | D6: BCM/hr | G6: 0.2 | H6: =P6-G6-I6 -> 0.1 | I6: =G6 -> 0.2 | K6: =D$3 -> 0.055 | L6: =(G6/G$3)+(H6/H$3)+(I6/I$3) -> 0.044 | M6: =D$4 -> 0.0083333333 | N6: =(G6/G$4)+(H6/H$4)+(I6/I$4) -> 0.042857143 | O6: =SUM(K6:N6) -> 0.15019048 | P6: 0.5 | Q6: =C$5*1/O6 -> 279.6449
G7: =G6 -> 0.2 | H7: =P7-G7-I7 -> 0.2 | I7: =I6 -> 0.2 | K7: =D$3 -> 0.055 | L7: =(G7/G$3)+(H7/H$3)+(I7/I$3) -> 0.048 | M7: =D$4 -> 0.0083333333 | N7: =(G7/G$4)+(H7/H$4)+(I7/I$4) -> 0.045714286 | O7: =SUM(K7:N7) -> 0.15704762 | P7: 0.6 | Q7: =C$5*1/O7 -> 267.43481
G8: =G7 -> 0.2 | H8: =P8-G8-I8 -> 0.3 | I8: =I7 -> 0.2 | K8: =D$3 -> 0.055 | L8: =(G8/G$3)+(H8/H$3)+(I8/I$3) -> 0.052 | M8: =D$4 -> 0.0083333333 | N8: =(G8/G$4)+(H8/H$4)+(I8/I$4) -> 0.048571429 | O8: =SUM(K8:N8) -> 0.16390476 | P8: 0.7 | Q8: =C$5*1/O8 -> 256.24637
G9: =G8 -> 0.2 | H9: =P9-G9-I9 -> 0.4 | I9: =I8 -> 0.2 | K9: =D$3 -> 0.055 | L9: =(G9/G$3)+(H9/H$3)+(I9/I$3) -> 0.056 | M9: =D$4 -> 0.0083333333 | N9: =(G9/G$4)+(H9/H$4)+(I9/I$4) -> 0.051428571 | O9: =SUM(K9:N9) -> 0.1707619 | P9: 0.8 | Q9: =C$5*1/O9 -> 245.9565
G10: =G9 -> 0.2 | H10: =P10-G10-I10 -> 0.5 | I10: =I9 -> 0.2 | K10: =D$3 -> 0.055 | L10: =(G10/G$3)+(H10/H$3)+(I10/I$3) -> 0.06 | M10: =D$4 -> 0.0083333333 | N10: =(G10/G$4)+(H10/H$4)+(I10/I$4) -> 0.054285714 | O10: =SUM(K10:N10) -> 0.17761905 | P10: 0.9 | Q10: =C$5*1/O10 -> 236.46113
G11: =G10 -> 0.2 | H11: =P11-G11-I11 -> 0.6 | I11: =I10 -> 0.2 | K11: =D$3 -> 0.055 | L11: =(G11/G$3)+(H11/H$3)+(I11/I$3) -> 0.064 | M11: =D$4 -> 0.0083333333 | N11: =(G11/G$4)+(H11/H$4)+(I11/I$4) -> 0.057142857 | O11: =SUM(K11:N11) -> 0.18447619 | P11: 1 | Q11: =C$5*1/O11 -> 227.67166
G12: =G11 -> 0.2 | H12: =P12-G12-I12 -> 0.7 | I12: =I11 -> 0.2 | K12: =D$3 -> 0.055 | L12: =(G12/G$3)+(H12/H$3)+(I12/I$3) -> 0.068 | M12: =D$4 -> 0.0083333333 | N12: =(G12/G$4)+(H12/H$4)+(I12/I$4) -> 0.06 | O12: =SUM(K12:N12) -> 0.19133333 | P12: 1.1 | Q12: =C$5*1/O12 -> 219.5122
G13: =G12 -> 0.2 | H13: =P13-G13-I13 -> 0.8 | I13: =I12 -> 0.2 | K13: =D$3 -> 0.055 | L13: =(G13/G$3)+(H13/H$3)+(I13/I$3) -> 0.072 | M13: =D$4 -> 0.0083333333 | N13: =(G13/G$4)+(H13/H$4)+(I13/I$4) -> 0.062857143 | O13: =SUM(K13:N13) -> 0.19819048 | P13: 1.2 | Q13: =C$5*1/O13 -> 211.91735
G14: =G13 -> 0.2 | H14: =P14-G14-I14 -> 0.9 | I14: =I13 -> 0.2 | K14: =D$3 -> 0.055 | L14: =(G14/G$3)+(H14/H$3)+(I14/I$3) -> 0.076 | M14: =D$4 -> 0.0083333333 | N14: =(G14/G$4)+(H14/H$4)+(I14/I$4) -> 0.065714286 | O14: =SUM(K14:N14) -> 0.20504762 | P14: 1.3 | Q14: =C$5*1/O14 -> 204.83047
G15: =G14 -> 0.2 | H15: =P15-G15-I15 -> 1 | I15: =I14 -> 0.2 | K15: =D$3 -> 0.055 | L15: =(G15/G$3)+(H15/H$3)+(I15/I$3) -> 0.08 | M15: =D$4 -> 0.0083333333 | N15: =(G15/G$4)+(H15/H$4)+(I15/I$4) -> 0.068571429 | O15: =SUM(K15:N15) -> 0.21190476 | P15: 1.4 | Q15: =C$5*1/O15 -> 198.20225
G16: =G15 -> 0.2 | H16: =P16-G16-I16 -> 1.1 | I16: =I15 -> 0.2 | K16: =D$3 -> 0.055 | L16: =(G16/G$3)+(H16/H$3)+(I16/I$3) -> 0.084 | M16: =D$4 -> 0.0083333333 | N16: =(G16/G$4)+(H16/H$4)+(I16/I$4) -> 0.071428571 | O16: =SUM(K16:N16) -> 0.2187619 | P16: 1.5 | Q16: =C$5*1/O16 -> 191.98955
G17: =G16 -> 0.2 | H17: =P17-G17-I17 -> 1.2 | I17: =I16 -> 0.2 | K17: =D$3 -> 0.055 | L17: =(G17/G$3)+(H17/H$3)+(I17/I$3) -> 0.088 | M17: =D$4 -> 0.0083333333 | N17: =(G17/G$4)+(H17/H$4)+(I17/I$4) -> 0.074285714 | O17: =SUM(K17:N17) -> 0.22561905 | P17: 1.6 | Q17: =C$5*1/O17 -> 186.1545
G18: =G17 -> 0.2 | H18: =P18-G18-I18 -> 1.3 | I18: =I17 -> 0.2 | K18: =D$3 -> 0.055 | L18: =(G18/G$3)+(H18/H$3)+(I18/I$3) -> 0.092 | M18: =D$4 -> 0.0083333333 | N18: =(G18/G$4)+(H18/H$4)+(I18/I$4) -> 0.077142857 | O18: =SUM(K18:N18) -> 0.23247619 | P18: 1.7 | Q18: =C$5*1/O18 -> 180.66366
... G105: =G104 -> 0.2 | H105: =P105-G105-I105 -> 10 | I105: =I104 -> 0.2 | K105: =D$3 -> 0.055 | L105: =(G105/G$3)+(H105/H$3)+(I105/I$3) -> 0.44 | M105: =D$4 -> 0.0083333333 | N105: =(G105/G$4)+(H105/H$4)+(I105/I$4) -> 0.32571429 | O105: =SUM(K105:N105) -> 0.82904762 | P105: 10.4 | Q105: =C$5*1/O105 -> 50.66054

Sheet Ref_fuel
A1: DUMMY
A3: MERK | B3: TYPE | C3: ACTIVITY | D3: Fuel Tank Cap. L | E3: Average | F3: Low | G3: Mid | H3: High
A4: ZS1EPRD528-4141 | B4: TRUCK, DUMP, HINO, ZS1EPRD528-4141 | C4: HAULING | E4: 30 | F4: 24 | G4: 30 | H4: 36
A5: ZS1EPPD-4141 | B5: TRUCK, DUMP, HINO, ZS1EPPD-4141 | C5: HAULING | E5: 30 | F5: 24 | G5: 30 | H5: 36
A6: XMT 650 | B6: WELDING MACHINE, ELECTRIC, MILLER, XMT 650, 650A @ 100% | C6: SUPPORT | E6: 1 | F6: 1 | G6: 1 | H6: 1
A7: Western Star | B7: WS-6900XD | C7: HAULING | E7: 38 | F7: 35 | G7: 38 | H7: 41
A8: WARMAN | B8: Water Pump | C8: SUPPORT | E8: 8 | F8: 5 | G8: 8 | H8: 10
A9: WARMAN | B9: Dewatering Pump | C9: SUPPORT | E9: 8 | F9: 5 | G9: 8 | H9: 10
A10: VOLVO TAD1643VE-HD | B10: KSB LCC-H200 | C10: SUPPORT | E10: 25 | F10: 20 | G10: 25 | H10: 30
A11: VOLVO TAD1643VE-HD | B11: VOLVO TAD1643VE-HD | C11: SUPPORT | E11: 25 | F11: 20 | G11: 25 | H11: 30
A12: VOLVO TAD1643VE | B12: KSB LCC-H200 | C12: SUPPORT | E12: 25 | F12: 20 | G12: 25 | H12: 30
A13: VOLVO TAD1642VE | B13: KSB LCC-H200 | C13: SUPPORT | E13: 25 | F13: 20 | G13: 25 | H13: 30
A14: VOLVO TAD1343VE | B14: KSB LCC-H150 | C14: SUPPORT | E14: 25 | F14: 20 | G14: 25 | H14: 30
A15: Volvo FM440 | B15: TRUCK, LIGHT, VOLVO , FM440,36T | C15: HAULING | E15: 30 | F15: 24 | G15: 30 | H15: 36
... A164: LTM 1055-3.2 | B164: CRANE, WHEEL, LIEBHERR, LTM 1055-3.2 55T | C164: SUPPORT | E164: 10 | F164: 8 | G164: 10 | H164: 12
A165: LSA 6X8-25 | B165: PUMP, KSB, LSA 6X6-25, CAT C27 | C165: SUPPORT | D165: Water Pump | E165: 40 | F165: 23 | G165: 40 | H165: 63
A166: LSA 6X8-25 | B166: PUMP, KSB, LSA 6X8-25, CAT C27 | C166: SUPPORT | D166: Water Pump | E166: 40 | F166: 23 | G166: 40 | H166: 63
A167: LOWBOY ,80T | B167: TRAILER, LOWBOY, SSB | C167: SUPPORT | E167: 50 | F167: 40 | G167: 50 | H167: 60
A168: LCC-H200-610.5K AB M1 | B168: WATER PUMP, Volvo Penta KSB, LCC-H200-610.5K AB M1 | C168: SUPPORT | E168: 30 | F168: 24 | G168: 30 | H168: 36
A169: KUBOTA | B169: Mega Tower | C169: SUPPORT | E169: 1 | F169: 1 | G169: 1 | H169: 1
A170: KUBOTA | B170: Mini Tower | C170: SUPPORT | E170: 1 | F170: 1 | G170: 1 | H170: 1
A171: KSB | B171: Water Pump | C171: SUPPORT | E171: 12 | F171: 8 | G171: 12 | H171: 15
A172: KOMATSU | B172: HD785-7 | C172: HAULING | E172: 77 | F172: 58 | G172: 77 | H172: 93
A173: KOMATSU | B173: PC2000-8 | C173: LOADING | E173: 100 | F173: 84 | G173: 100 | H173: 147
A174: KOMATSU | B174: D 85 E-SS DZ | C174: SUPPORT | E174: 27 | F174: 18 | G174: 27 | H174: 37
A175: KOMATSU | B175: D155A-6 | C175: SUPPORT | E175: 34 | F175: 23 | G175: 34 | H175: 46
A176: KOMATSU | B176: GD535-5 MG | C176: SUPPORT | E176: 11 | F176: 8 | G176: 11 | H176: 17
A177: KOMATSU | B177: GD825A-2 | C177: SUPPORT | E177: 27 | F177: 18 | G177: 27 | H177: 35
A178: KOMATSU | B178: PC200-8MO | C178: SUPPORT | E178: 12 | F178: 8 | G178: 12 | H178: 19
... A184: KOMATSU | B184: HD4657RPM | C184: HAULING | E184: 47 | F184: 33 | G184: 47 | H184: 66
A185: KOMATSU | B185: HD7857WT | C185: HAULING | D185: 1308 | E185: 77 | F185: 58 | G185: 77 | H185: 93
A186: KOMATSU | B186: HD7857MUD | C186: HAULING | D186: 1308 | E186: 77 | F186: 58 | G186: 77 | H186: 93
A187: KOMATSU | B187: HD7857 | C187: HAULING | D187: 1308 | E187: 77 | F187: 58 | G187: 77 | H187: 93
A188: KOMATSU | B188: HD7858 | C188: HAULING | D188: 1308 | E188: 77 | F188: 58 | G188: 77 | H188: 93
A189: KOMATSU | B189: D155A6R | C189: HAULING | E189: 29 | F189: 17 | G189: 29 | H189: 40
A190: KOMATSU | B190: D155A-6R | C190: HAULING | E190: 29 | F190: 17 | G190: 29 | H190: 40
A191: KOMATSU | B191: D375A-6R | C191: HAULING | E191: 64 | F191: 47 | G191: 64 | H191: 80
A192: KOMATSU | B192: PC1250SP8 | C192: LOADING | E192: 64 | F192: 52 | G192: 64 | H192: 87
A193: KOMATSU | B193: PC1250-11R | C193: LOADING | E193: 59 | F193: 48 | G193: 59 | H193: 81
A194: KOMATSU | B194: EX12006 | C194: LOADING | E194: 65 | F194: 50 | G194: 65 | H194: 80
...

Sheet DUMMY DATA
B2: UNIT | C2: QTY | D2: ACTIVITY | E2: FC (L/H)
B3: HT 2600 | C3: 1 | D3: LOADING | E3: 190
B4: PC 1250 | C4: 7 | D4: LOADING | E4: 93.33
B5: PC 1250_Mud | C5: 1 | D5: LOADING | E5: 97.583333
B6: PC 2000 | C6: 16 | D6: LOADING | E6: 125
B7: PC 2000_Mud | C7: 1 | D7: LOADING | E7: 125
B8: PC 3400 | C8: 1 | D8: LOADING | E8: 195.625
B9: HD785-7 | C9: 205 | D9: HAULING | E9: 75
B10: HD785-7MUD | C10: 28 | D10: HAULING | E10: 75
B11: MID DRILLING | C11: 1 | D11: SUPPORT | E11: 54.166667
B12: SMALL DRILLING | C12: 4 | D12: SUPPORT | E12: 28.055556
B13: Booster Pump | C13: 7 | D13: DEWATERING | E13: 50
B14: Dragflow | C14: 4 | D14: DEWATERING | E14: 45
... B40: WTHD | C40: 14 | D40: SUPPORT | E40: 75.991667
